<?xml version="1.0" encoding="UTF-8"?>
<robot  xmlns:xacro="http://www.ros.org/wiki/xacro" name="vscmg">

    <link name="world"></link>
    <link name="b1"></link>
    <link name="b2"></link>

    <material name="blue">
        <color rgba="0 0 0.8 1" />
    </material>

    <material name="platform_color">
        <color rgba="0.9 0.8 0.7 1.0" />
    </material>

    <material name="tripod_color">
        <color rgba="1.0 1.0 1.0 1.0" />
    </material>

    <material name="gimbal_color">
        <color rgba="0.3 0.8 0.05 1.0" />
    </material>

    <material name="rw_color">
        <color rgba="0.1 0.32 0.78 1.0" />
    </material>

    <!-- Triapod link -->
    <link name="tripod">
        <inertial>
            <origin xyz="0.0 0.0 0.0" rpy="0.0 0.0 0.0" />
            <mass value="0.0" />
            <inertia ixx="0.0" ixy="0.0" ixz="0.0" iyy="0.0" iyz="0.0" izz="0.0" />
        </inertial>
        <visual name="">
            <origin xyz="0.0 0.0 0.05" rpy="0.0 0.0 0.0" />
            <geometry>
                <mesh filename="package://vscmg_description/meshes/tripod.stl" scale="0.001 0.001 0.001" />
            </geometry>
            <material name="tripod_color" />
        </visual>
        <collision>
            <origin xyz="0.0 0.0 0.05" rpy="0.0 0.0 0.0" />
            <geometry>
                <mesh filename="package://vscmg_description/meshes/tripod.stl" scale="0.001 0.001 0.001" />
            </geometry>
        </collision>
    </link>


    <link name="platform">
        <inertial>
            <origin xyz="0.0 0.0 0.0" rpy="0.0 0.0 0.0" />
            <mass value="0.0" />
            <inertia ixx="0.0" ixy="0.0" ixz="0.0" iyy="0.0" iyz="0.0" izz="0.0" />
        </inertial>
        <visual name="">
            <origin xyz="0.0 0.0 0.05" rpy="0.0 0.0 0.0" />
            <geometry>
                <mesh filename="package://vscmg_description/meshes/base.stl" scale="0.001 0.001 0.001" />
            </geometry>
            <material name="platform_color" />
        </visual>
        <collision>
            <origin xyz="0.0 0.0 0.05" rpy="0.0 0.0 0.0" />
            <geometry>
                <mesh filename="package://vscmg_description/meshes/base.stl" scale="0.001 0.001 0.001" />
            </geometry>
        </collision>
    </link>

    <!-- fixed joint from world to tripod -->
    <joint name="world_to_tripod" type="fixed">
        <origin xyz="0.0 0.0 0.0" rpy="0.0 0.0 0.0" />
        <parent link="world" />
        <child link="tripod" />
    </joint>


    <!-- Spherical joint from tripod to platform -->
    <joint name="yaw" type="continuous">
        <origin xyz="0.0 0.0 0.0" rpy="0.0 0.0 0.0" />
        <parent link="tripod" />
        <child link="b1" />
        <axis xyz="0.0 0.0 1.0" />
    </joint>
    <joint name="pitch" type="revolute">
        <origin xyz="0.0 0.0 0.0" rpy="0.0 0.0 0.0" />
        <parent link="b1" />
        <child link="b2" />
        <axis xyz="0.0 1.0 0.0" />
        <limit lower="-0.5235" upper="0.5235" effort="0.0" velocity="0.0" />
    </joint>
    <joint name="roll" type="revolute">
        <origin xyz="0.0 0.0 0.0" rpy="0.0 0.0 0.0" />
        <parent link="b2" />
        <child link="platform" />
        <axis xyz="1.0 0.0 0.0" />
        <limit lower="-0.5235" upper="0.5235" effort="0.0" velocity="0.0" />
    </joint>

    <!-- Gimbal 1 link -->
    <link name="gimbal_frame_1">
        <inertial>
            <origin xyz="0.0 0.0 0.0" rpy="0.0 0.0 0.0" />
            <mass value="0.0" />
            <inertia ixx="0.0" ixy="0.0" ixz="0.0" iyy="0.0" iyz="0.0" izz="0.0" />
        </inertial>
        <visual name="">
            <origin xyz="0.0 0.0032 -0.0142" rpy="0.0 0.0 0.0" />
            <geometry>
                <mesh filename="package://vscmg_description/meshes/gimbal.stl" scale="0.001 0.001 0.001" />
            </geometry>
            <material name="gimbal_color" />
        </visual>
        <collision>
            <origin xyz="0.0 0.0032 -0.0142" rpy="0.0 0.0 0.0" />
            <geometry>
                <mesh filename="package://vscmg_description/meshes/gimbal.stl" scale="0.001 0.001 0.001" />
            </geometry>
        </collision>
    </link>

    <joint name="gimbal_1" type="continuous">
        <origin xyz="0.0 0.074 0.058" rpy="-0.9553 0.0 0.0" />
        <parent link="platform" />
        <child link="gimbal_frame_1" />
        <axis xyz="0.0 1.0 0.0" />
        <limit lower="0.0" upper="0.0" effort="0.0" velocity="0.0" />
    </joint>

    <!-- Gimbal 2 link -->
    <link name="gimbal_frame_2">
        <inertial>
            <origin xyz="0.0 0.0 0.0" rpy="0.0 0.0 0.0" />
            <mass value="0.0" />
            <inertia ixx="0.0" ixy="0.0" ixz="0.0" iyy="0.0" iyz="0.0" izz="0.0" />
        </inertial>
        <visual name="">
            <origin xyz="0.0 0.0032 -0.0142" rpy="0.0 0.0 0.0" />
            <geometry>
                <mesh filename="package://vscmg_description/meshes/gimbal.stl" scale="0.001 0.001 0.001" />
            </geometry>
            <material name="gimbal_color" />
        </visual>
        <collision>
            <origin xyz="0.0 0.0032 -0.0142" rpy="0.0 0.0 0.0" />
            <geometry>
                <mesh filename="package://vscmg_description/meshes/gimbal.stl" scale="0.001 0.001 0.001" />
            </geometry>
        </collision>
    </link>

    <joint name="gimbal_2" type="continuous">
        <origin xyz="-0.074 0.0 0.058" rpy="-0.9553 0.0 1.5707963267948966" />
        <parent link="platform" />
        <child link="gimbal_frame_2" />
        <axis xyz="0.0 1.0 0.0" />
        <limit lower="0.0" upper="0.0" effort="0.0" velocity="0.0" />
    </joint>


    <!-- Gimbal 3 link -->
    <link name="gimbal_frame_3">
        <inertial>
            <origin xyz="0.0 0.0 0.0" rpy="0.0 0.0 0.0" />
            <mass value="0.0" />
            <inertia ixx="0.0" ixy="0.0" ixz="0.0" iyy="0.0" iyz="0.0" izz="0.0" />
        </inertial>
        <visual name="">
            <origin xyz="0.0 0.0032 -0.0142" rpy="0.0 0.0 0.0" />
            <geometry>
                <mesh filename="package://vscmg_description/meshes/gimbal.stl" scale="0.001 0.001 0.001" />
            </geometry>
            <material name="gimbal_color" />
        </visual>
        <collision>
            <origin xyz="0.0 0.0032 -0.0142" rpy="0.0 0.0 0.0" />
            <geometry>
                <mesh filename="package://vscmg_description/meshes/gimbal.stl" scale="0.001 0.001 0.001" />
            </geometry>
        </collision>
    </link>

    <joint name="gimbal_3" type="continuous">
        <origin xyz="0.0 -0.074 0.058" rpy="-0.9553 0.0 3.141592653589793" />
        <parent link="platform" />
        <child link="gimbal_frame_3" />
        <axis xyz="0.0 1.0 0.0" />
        <limit lower="0.0" upper="0.0" effort="0.0" velocity="0.0" />
    </joint>


    <!-- Gimbal 4 link -->
    <link name="gimbal_frame_4">
        <inertial>
            <origin xyz="0.0 0.0 0.0" rpy="0.0 0.0 0.0" />
            <mass value="0.0" />
            <inertia ixx="0.0" ixy="0.0" ixz="0.0" iyy="0.0" iyz="0.0" izz="0.0" />
        </inertial>
        <visual name="">
            <origin xyz="0.0 0.0032 -0.0142" rpy="0.0 0.0 0.0" />
            <geometry>
                <mesh filename="package://vscmg_description/meshes/gimbal.stl" scale="0.001 0.001 0.001" />
            </geometry>
            <material name="gimbal_color" />
        </visual>
        <collision>
            <origin xyz="0.0 0.0032 -0.0142" rpy="0.0 0.0 0.0" />
            <geometry>
                <mesh filename="package://vscmg_description/meshes/gimbal.stl" scale="0.001 0.001 0.001" />
            </geometry>
        </collision>
    </link>

    <joint name="gimbal_4" type="continuous">
        <origin xyz="0.074 0.0 0.058" rpy="-0.9553 0.0 -1.5707963267948966" />
        <parent link="platform" />
        <child link="gimbal_frame_4" />
        <axis xyz="0.0 1.0 0.0" />
        <limit lower="0.0" upper="0.0" effort="0.0" velocity="0.0" />
    </joint>


    <link name="rw_frame_1">
        <inertial>
            <origin xyz="0.0 0.0 0.0" rpy="0.0 0.0 0.0" />
            <mass value="0.0" />
            <inertia ixx="0.0" ixy="0.0" ixz="0.0" iyy="0.0" iyz="0.0" izz="0.0" />
        </inertial>
        <visual name="">
            <origin xyz="0.0 0.0 0.0" rpy="0.0 0.0 0.0" />
            <geometry>
                <mesh filename="package://vscmg_description/meshes/rw1.stl" scale="0.001 0.001 0.001" />
            </geometry>
            <material name="rw_color" />
        </visual>
        <collision>
            <origin xyz="0.0 0.0 0.0" rpy="0.0 0.0 0.0" />
            <geometry>
                <box size="0.0 0.0 0.0" />
            </geometry>
        </collision>
    </link>

    <joint name="rw_1" type="continuous">
        <origin xyz="0.0 0.0 0.0" rpy="0.0 0.0 0" />
        <parent link="gimbal_frame_1" />
        <child link="rw_frame_1" />
        <axis xyz="0.0 0.0 1.0" />
        <limit lower="0.0" upper="0.0" effort="0.0" velocity="0.0" />
    </joint>


    <link name="rw_frame_2">
        <inertial>
            <origin xyz="0.0 0.0 0.0" rpy="0.0 0.0 0.0" />
            <mass value="0.0" />
            <inertia ixx="0.0" ixy="0.0" ixz="0.0" iyy="0.0" iyz="0.0" izz="0.0" />
        </inertial>
        <visual name="">
            <origin xyz="0.0 0.0 0.0" rpy="0.0 0.0 0.0" />
            <geometry>
                <mesh filename="package://vscmg_description/meshes/rw1.stl" scale="0.001 0.001 0.001" />
            </geometry>
            <material name="rw_color" />
        </visual>
        <collision>
            <origin xyz="0.0 0.0 0.0" rpy="0.0 0.0 0.0" />
            <geometry>
                <box size="0.0 0.0 0.0" />
            </geometry>
        </collision>
    </link>

    <joint name="rw_2" type="continuous">
        <origin xyz="0.0 0.0 0.0" rpy="0.0 0.0 0" />
        <parent link="gimbal_frame_2" />
        <child link="rw_frame_2" />
        <axis xyz="0.0 0.0 1.0" />
        <limit lower="0.0" upper="0.0" effort="0.0" velocity="0.0" />
    </joint>


    <link name="rw_frame_3">
        <inertial>
            <origin xyz="0.0 0.0 0.0" rpy="0.0 0.0 0.0" />
            <mass value="0.0" />
            <inertia ixx="0.0" ixy="0.0" ixz="0.0" iyy="0.0" iyz="0.0" izz="0.0" />
        </inertial>
        <visual name="">
            <origin xyz="0.0 0.0 0.0" rpy="0.0 0.0 0.0" />
            <geometry>
                <mesh filename="package://vscmg_description/meshes/rw1.stl" scale="0.001 0.001 0.001" />
            </geometry>
            <material name="rw_color" />
        </visual>
        <collision>
            <origin xyz="0.0 0.0 0.0" rpy="0.0 0.0 0.0" />
            <geometry>
                <box size="0.0 0.0 0.0" />
            </geometry>
        </collision>
    </link>

    <joint name="rw_3" type="continuous">
        <origin xyz="0.0 0.0 0.0" rpy="0.0 0.0 0" />
        <parent link="gimbal_frame_3" />
        <child link="rw_frame_3" />
        <axis xyz="0.0 0.0 1.0" />
        <limit lower="0.0" upper="0.0" effort="0.0" velocity="0.0" />
    </joint>


    <link name="rw_frame_4">
        <inertial>
            <origin xyz="0.0 0.0 0.0" rpy="0.0 0.0 0.0" />
            <mass value="0.0" />
            <inertia ixx="0.0" ixy="0.0" ixz="0.0" iyy="0.0" iyz="0.0" izz="0.0" />
        </inertial>
        <visual name="">
            <origin xyz="0.0 0.0 0.0" rpy="0.0 0.0 0.0" />
            <geometry>
                <mesh filename="package://vscmg_description/meshes/rw1.stl" scale="0.001 0.001 0.001" />
            </geometry>
            <material name="rw_color" />
        </visual>
        <collision>
            <origin xyz="0.0 0.0 0.0" rpy="0.0 0.0 0.0" />
            <geometry>
                <box size="0.0 0.0 0.0" />
            </geometry>
        </collision>
    </link>

    <joint name="rw_4" type="continuous">
        <origin xyz="0.0 0.0 0.0" rpy="0.0 0.0 0" />
        <parent link="gimbal_frame_4" />
        <child link="rw_frame_4" />
        <axis xyz="0.0 0.0 1.0" />
        <limit lower="0.0" upper="0.0" effort="0.0" velocity="0.0" />
    </joint>
</robot>