<?xml version="1.0" ?>
<!-- =================================================================================== -->
<!-- |    This document was autogenerated by xacro from vscmg.urdf.xacro               | -->
<!-- |    EDITING THIS FILE BY HAND IS NOT RECOMMENDED                                 | -->
<!-- =================================================================================== -->
<robot name="vscmg">
  <material name="blue">
    <color rgba="0 0 0.8 1"/>
  </material>
  <material name="platform_color">
    <color rgba="0.7843137254901961 0.7843137254901961 0.7843137254901961 1.0"/>
  </material>
  <material name="tripod_color">
    <color rgba="0.1 0.1 0.1 1.0"/>
  </material>
  <material name="cmg_frame_color">
    <color rgba="1.0 1.0 1.0 1.0"/>
  </material>
  <material name="gimbal_color">
    <color rgba="0.3 0.8 0.05 1.0"/>
  </material>
  <material name="rw_color">
    <color rgba="0.23 0.29 0.33 1.0"/>
  </material>
  <link name="floating_base"/>
  <joint name="floating_base_joint" type="fixed">
    <origin rpy="0.0 0.0 0.0" xyz="0.0 0.0 0.0"/>
    <parent link="floating_base"/>
    <child link="platform"/>
    <axis xyz="0.0 0.0 0.0"/>
    <limit effort="0.0" lower="0.0" upper="0.0" velocity="0.0"/>
  </joint>
  <link name="platform">
    <inertial>
      <origin rpy="0.0 0.0 0.0" xyz="0.0 0.0 0.0"/>
      <mass value="0.0"/>
      <inertia ixx="0.0" ixy="0.0" ixz="0.0" iyy="0.0" iyz="0.0" izz="0.0"/>
    </inertial>
    <visual name="">
      <origin rpy="0.0 0.0 0.0" xyz="0.0 0.0 0.05"/>
      <geometry>
        <mesh filename="package://vscmg_description/meshes/base.stl" scale="0.001 0.001 0.001"/>
      </geometry>
      <material name="platform_color"/>
    </visual>
    <collision>
      <origin rpy="0.0 0.0 0.0" xyz="0.0 0.0 0.05"/>
      <geometry>
        <mesh filename="package://vscmg_description/meshes/base.stl" scale="0.001 0.001 0.001"/>
      </geometry>
    </collision>
  </link>
  <!-- SGCMG base frame -->
  <link name="sgcmg_frame_1">
    <inertial>
      <origin rpy="0.0 0.0 0.0" xyz="0.0 0.0 0.0"/>
      <mass value="0.0"/>
      <inertia ixx="0.0" ixy="0.0" ixz="0.0" iyy="0.0" iyz="0.0" izz="0.0"/>
    </inertial>
    <visual name="">
      <origin rpy="0.0 0.0 0.0" xyz="0.0 0.0 0.0"/>
      <geometry>
        <mesh filename="package://vscmg_description/meshes/cmg_frame_z.stl" scale="0.001 0.001 0.001"/>
      </geometry>
      <material name="cmg_frame_color"/>
    </visual>
    <collision>
      <origin rpy="0.0 0.0 0.0" xyz="0.0 0.0 0.0"/>
      <geometry>
        <mesh filename="package://vscmg_description/meshes/cmg_frame_z.stl" scale="0.001 0.001 0.001"/>
      </geometry>
    </collision>
  </link>
  <!-- SGCMG Gimbal  -->
  <link name="gimbal_frame_1">
    <inertial>
      <origin rpy="0.0 0.0 0.0" xyz="0.0 0.0 0.0"/>
      <mass value="0.0"/>
      <inertia ixx="0.0" ixy="0.0" ixz="0.0" iyy="0.0" iyz="0.0" izz="0.0"/>
    </inertial>
    <visual name="">
      <origin rpy="0.0 0.0 0.0" xyz="0.0 0.0 0.0"/>
      <geometry>
        <mesh filename="package://vscmg_description/meshes/gimbal_frame_z.stl" scale="0.001 0.001 0.001"/>
      </geometry>
      <material name="gimbal_color"/>
    </visual>
    <collision>
      <origin rpy="0.0 0.0 0.0" xyz="0.0 0.0 0.0"/>
      <geometry>
        <mesh filename="package://vscmg_description/meshes/gimbal_frame_z.stl" scale="0.001 0.001 0.001"/>
      </geometry>
    </collision>
  </link>
  <!-- SGCMG Reaction Wheel  -->
  <link name="rw_frame_1">
    <inertial>
      <origin rpy="0.0 0.0 0.0" xyz="0.0 0.0 0.0"/>
      <mass value="0.0"/>
      <inertia ixx="0.0" ixy="0.0" ixz="0.0" iyy="0.0" iyz="0.0" izz="0.0"/>
    </inertial>
    <visual name="">
      <origin rpy="0.0 0.0 0.0" xyz="0.0 0.0 0.0"/>
      <geometry>
        <mesh filename="package://vscmg_description/meshes/rw_y.stl" scale="0.001 0.001 0.001"/>
      </geometry>
      <material name="rw_color"/>
    </visual>
    <collision>
      <origin rpy="0.0 0.0 0.0" xyz="0.0 0.0 0.0"/>
      <geometry>
        <mesh filename="package://vscmg_description/meshes/rw_y.stl" scale="0.001 0.001 0.001"/>
      </geometry>
    </collision>
  </link>
  <!-- Fixed joint of SGCMG attached to parent -->
  <joint name="j1" type="fixed">
    <origin rpy="0.6154797086703873 0.0 0.0" xyz="4.500576986866523e-18 0.0735 0.059"/>
    <parent link="platform"/>
    <child link="sgcmg_frame_1"/>
    <axis xyz="0.0 0.0 0.0"/>
    <limit effort="0.0" lower="0.0" upper="0.0" velocity="0.0"/>
  </joint>
  <!-- Joint at Gimbal Axis -->
  <!-- <joint name="sgcmg_frame_${id}_to_gimbal_frame_${id}" type="continuous"> -->
  <joint name="gimbal_1" type="continuous">
    <origin rpy="0.0 0.0 0.0" xyz="0.0 0.0 0.0"/>
    <parent link="sgcmg_frame_1"/>
    <child link="gimbal_frame_1"/>
    <axis xyz="0.0 0.0 1.0"/>
    <limit effort="0.0" lower="0.0" upper="0.0" velocity="0.0"/>
  </joint>
  <!-- Joint at Reaction wheel spin Axis -->
  <!-- <joint name="rw_${id}_to_sgcmg_frame_${id}" type="continuous">  -->
  <joint name="wheel_1" type="continuous">
    <origin rpy="0.0 0.0 0.0" xyz="0.0 0.0 0.0"/>
    <parent link="gimbal_frame_1"/>
    <child link="rw_frame_1"/>
    <axis xyz="0.0 1.0 0.0"/>
    <limit effort="0.0" lower="0.0" upper="0.0" velocity="0.0"/>
  </joint>
  <!-- SGCMG base frame -->
  <link name="sgcmg_frame_2">
    <inertial>
      <origin rpy="0.0 0.0 0.0" xyz="0.0 0.0 0.0"/>
      <mass value="0.0"/>
      <inertia ixx="0.0" ixy="0.0" ixz="0.0" iyy="0.0" iyz="0.0" izz="0.0"/>
    </inertial>
    <visual name="">
      <origin rpy="0.0 0.0 0.0" xyz="0.0 0.0 0.0"/>
      <geometry>
        <mesh filename="package://vscmg_description/meshes/cmg_frame_z.stl" scale="0.001 0.001 0.001"/>
      </geometry>
      <material name="cmg_frame_color"/>
    </visual>
    <collision>
      <origin rpy="0.0 0.0 0.0" xyz="0.0 0.0 0.0"/>
      <geometry>
        <mesh filename="package://vscmg_description/meshes/cmg_frame_z.stl" scale="0.001 0.001 0.001"/>
      </geometry>
    </collision>
  </link>
  <!-- SGCMG Gimbal  -->
  <link name="gimbal_frame_2">
    <inertial>
      <origin rpy="0.0 0.0 0.0" xyz="0.0 0.0 0.0"/>
      <mass value="0.0"/>
      <inertia ixx="0.0" ixy="0.0" ixz="0.0" iyy="0.0" iyz="0.0" izz="0.0"/>
    </inertial>
    <visual name="">
      <origin rpy="0.0 0.0 0.0" xyz="0.0 0.0 0.0"/>
      <geometry>
        <mesh filename="package://vscmg_description/meshes/gimbal_frame_z.stl" scale="0.001 0.001 0.001"/>
      </geometry>
      <material name="gimbal_color"/>
    </visual>
    <collision>
      <origin rpy="0.0 0.0 0.0" xyz="0.0 0.0 0.0"/>
      <geometry>
        <mesh filename="package://vscmg_description/meshes/gimbal_frame_z.stl" scale="0.001 0.001 0.001"/>
      </geometry>
    </collision>
  </link>
  <!-- SGCMG Reaction Wheel  -->
  <link name="rw_frame_2">
    <inertial>
      <origin rpy="0.0 0.0 0.0" xyz="0.0 0.0 0.0"/>
      <mass value="0.0"/>
      <inertia ixx="0.0" ixy="0.0" ixz="0.0" iyy="0.0" iyz="0.0" izz="0.0"/>
    </inertial>
    <visual name="">
      <origin rpy="0.0 0.0 0.0" xyz="0.0 0.0 0.0"/>
      <geometry>
        <mesh filename="package://vscmg_description/meshes/rw_y.stl" scale="0.001 0.001 0.001"/>
      </geometry>
      <material name="rw_color"/>
    </visual>
    <collision>
      <origin rpy="0.0 0.0 0.0" xyz="0.0 0.0 0.0"/>
      <geometry>
        <mesh filename="package://vscmg_description/meshes/rw_y.stl" scale="0.001 0.001 0.001"/>
      </geometry>
    </collision>
  </link>
  <!-- Fixed joint of SGCMG attached to parent -->
  <joint name="j2" type="fixed">
    <origin rpy="0.6154797086703873 0.0 1.5707963267948966" xyz="-0.0735 9.001153973733046e-18 0.059"/>
    <parent link="platform"/>
    <child link="sgcmg_frame_2"/>
    <axis xyz="0.0 0.0 0.0"/>
    <limit effort="0.0" lower="0.0" upper="0.0" velocity="0.0"/>
  </joint>
  <!-- Joint at Gimbal Axis -->
  <!-- <joint name="sgcmg_frame_${id}_to_gimbal_frame_${id}" type="continuous"> -->
  <joint name="gimbal_2" type="continuous">
    <origin rpy="0.0 0.0 0.0" xyz="0.0 0.0 0.0"/>
    <parent link="sgcmg_frame_2"/>
    <child link="gimbal_frame_2"/>
    <axis xyz="0.0 0.0 1.0"/>
    <limit effort="0.0" lower="0.0" upper="0.0" velocity="0.0"/>
  </joint>
  <!-- Joint at Reaction wheel spin Axis -->
  <!-- <joint name="rw_${id}_to_sgcmg_frame_${id}" type="continuous">  -->
  <joint name="wheel_2" type="continuous">
    <origin rpy="0.0 0.0 0.0" xyz="0.0 0.0 0.0"/>
    <parent link="gimbal_frame_2"/>
    <child link="rw_frame_2"/>
    <axis xyz="0.0 1.0 0.0"/>
    <limit effort="0.0" lower="0.0" upper="0.0" velocity="0.0"/>
  </joint>
  <!-- SGCMG base frame -->
  <link name="sgcmg_frame_3">
    <inertial>
      <origin rpy="0.0 0.0 0.0" xyz="0.0 0.0 0.0"/>
      <mass value="0.0"/>
      <inertia ixx="0.0" ixy="0.0" ixz="0.0" iyy="0.0" iyz="0.0" izz="0.0"/>
    </inertial>
    <visual name="">
      <origin rpy="0.0 0.0 0.0" xyz="0.0 0.0 0.0"/>
      <geometry>
        <mesh filename="package://vscmg_description/meshes/cmg_frame_z.stl" scale="0.001 0.001 0.001"/>
      </geometry>
      <material name="cmg_frame_color"/>
    </visual>
    <collision>
      <origin rpy="0.0 0.0 0.0" xyz="0.0 0.0 0.0"/>
      <geometry>
        <mesh filename="package://vscmg_description/meshes/cmg_frame_z.stl" scale="0.001 0.001 0.001"/>
      </geometry>
    </collision>
  </link>
  <!-- SGCMG Gimbal  -->
  <link name="gimbal_frame_3">
    <inertial>
      <origin rpy="0.0 0.0 0.0" xyz="0.0 0.0 0.0"/>
      <mass value="0.0"/>
      <inertia ixx="0.0" ixy="0.0" ixz="0.0" iyy="0.0" iyz="0.0" izz="0.0"/>
    </inertial>
    <visual name="">
      <origin rpy="0.0 0.0 0.0" xyz="0.0 0.0 0.0"/>
      <geometry>
        <mesh filename="package://vscmg_description/meshes/gimbal_frame_z.stl" scale="0.001 0.001 0.001"/>
      </geometry>
      <material name="gimbal_color"/>
    </visual>
    <collision>
      <origin rpy="0.0 0.0 0.0" xyz="0.0 0.0 0.0"/>
      <geometry>
        <mesh filename="package://vscmg_description/meshes/gimbal_frame_z.stl" scale="0.001 0.001 0.001"/>
      </geometry>
    </collision>
  </link>
  <!-- SGCMG Reaction Wheel  -->
  <link name="rw_frame_3">
    <inertial>
      <origin rpy="0.0 0.0 0.0" xyz="0.0 0.0 0.0"/>
      <mass value="0.0"/>
      <inertia ixx="0.0" ixy="0.0" ixz="0.0" iyy="0.0" iyz="0.0" izz="0.0"/>
    </inertial>
    <visual name="">
      <origin rpy="0.0 0.0 0.0" xyz="0.0 0.0 0.0"/>
      <geometry>
        <mesh filename="package://vscmg_description/meshes/rw_y.stl" scale="0.001 0.001 0.001"/>
      </geometry>
      <material name="rw_color"/>
    </visual>
    <collision>
      <origin rpy="0.0 0.0 0.0" xyz="0.0 0.0 0.0"/>
      <geometry>
        <mesh filename="package://vscmg_description/meshes/rw_y.stl" scale="0.001 0.001 0.001"/>
      </geometry>
    </collision>
  </link>
  <!-- Fixed joint of SGCMG attached to parent -->
  <joint name="j3" type="fixed">
    <origin rpy="0.6154797086703873 0.0 3.141592653589793" xyz="-1.3501730960599567e-17 -0.0735 0.059"/>
    <parent link="platform"/>
    <child link="sgcmg_frame_3"/>
    <axis xyz="0.0 0.0 0.0"/>
    <limit effort="0.0" lower="0.0" upper="0.0" velocity="0.0"/>
  </joint>
  <!-- Joint at Gimbal Axis -->
  <!-- <joint name="sgcmg_frame_${id}_to_gimbal_frame_${id}" type="continuous"> -->
  <joint name="gimbal_3" type="continuous">
    <origin rpy="0.0 0.0 0.0" xyz="0.0 0.0 0.0"/>
    <parent link="sgcmg_frame_3"/>
    <child link="gimbal_frame_3"/>
    <axis xyz="0.0 0.0 1.0"/>
    <limit effort="0.0" lower="0.0" upper="0.0" velocity="0.0"/>
  </joint>
  <!-- Joint at Reaction wheel spin Axis -->
  <!-- <joint name="rw_${id}_to_sgcmg_frame_${id}" type="continuous">  -->
  <joint name="wheel_3" type="continuous">
    <origin rpy="0.0 0.0 0.0" xyz="0.0 0.0 0.0"/>
    <parent link="gimbal_frame_3"/>
    <child link="rw_frame_3"/>
    <axis xyz="0.0 1.0 0.0"/>
    <limit effort="0.0" lower="0.0" upper="0.0" velocity="0.0"/>
  </joint>
  <!-- SGCMG base frame -->
  <link name="sgcmg_frame_4">
    <inertial>
      <origin rpy="0.0 0.0 0.0" xyz="0.0 0.0 0.0"/>
      <mass value="0.0"/>
      <inertia ixx="0.0" ixy="0.0" ixz="0.0" iyy="0.0" iyz="0.0" izz="0.0"/>
    </inertial>
    <visual name="">
      <origin rpy="0.0 0.0 0.0" xyz="0.0 0.0 0.0"/>
      <geometry>
        <mesh filename="package://vscmg_description/meshes/cmg_frame_z.stl" scale="0.001 0.001 0.001"/>
      </geometry>
      <material name="cmg_frame_color"/>
    </visual>
    <collision>
      <origin rpy="0.0 0.0 0.0" xyz="0.0 0.0 0.0"/>
      <geometry>
        <mesh filename="package://vscmg_description/meshes/cmg_frame_z.stl" scale="0.001 0.001 0.001"/>
      </geometry>
    </collision>
  </link>
  <!-- SGCMG Gimbal  -->
  <link name="gimbal_frame_4">
    <inertial>
      <origin rpy="0.0 0.0 0.0" xyz="0.0 0.0 0.0"/>
      <mass value="0.0"/>
      <inertia ixx="0.0" ixy="0.0" ixz="0.0" iyy="0.0" iyz="0.0" izz="0.0"/>
    </inertial>
    <visual name="">
      <origin rpy="0.0 0.0 0.0" xyz="0.0 0.0 0.0"/>
      <geometry>
        <mesh filename="package://vscmg_description/meshes/gimbal_frame_z.stl" scale="0.001 0.001 0.001"/>
      </geometry>
      <material name="gimbal_color"/>
    </visual>
    <collision>
      <origin rpy="0.0 0.0 0.0" xyz="0.0 0.0 0.0"/>
      <geometry>
        <mesh filename="package://vscmg_description/meshes/gimbal_frame_z.stl" scale="0.001 0.001 0.001"/>
      </geometry>
    </collision>
  </link>
  <!-- SGCMG Reaction Wheel  -->
  <link name="rw_frame_4">
    <inertial>
      <origin rpy="0.0 0.0 0.0" xyz="0.0 0.0 0.0"/>
      <mass value="0.0"/>
      <inertia ixx="0.0" ixy="0.0" ixz="0.0" iyy="0.0" iyz="0.0" izz="0.0"/>
    </inertial>
    <visual name="">
      <origin rpy="0.0 0.0 0.0" xyz="0.0 0.0 0.0"/>
      <geometry>
        <mesh filename="package://vscmg_description/meshes/rw_y.stl" scale="0.001 0.001 0.001"/>
      </geometry>
      <material name="rw_color"/>
    </visual>
    <collision>
      <origin rpy="0.0 0.0 0.0" xyz="0.0 0.0 0.0"/>
      <geometry>
        <mesh filename="package://vscmg_description/meshes/rw_y.stl" scale="0.001 0.001 0.001"/>
      </geometry>
    </collision>
  </link>
  <!-- Fixed joint of SGCMG attached to parent -->
  <joint name="j4" type="fixed">
    <origin rpy="0.6154797086703873 0.0 4.71238898038469" xyz="0.0735 -1.8002307947466092e-17 0.059"/>
    <parent link="platform"/>
    <child link="sgcmg_frame_4"/>
    <axis xyz="0.0 0.0 0.0"/>
    <limit effort="0.0" lower="0.0" upper="0.0" velocity="0.0"/>
  </joint>
  <!-- Joint at Gimbal Axis -->
  <!-- <joint name="sgcmg_frame_${id}_to_gimbal_frame_${id}" type="continuous"> -->
  <joint name="gimbal_4" type="continuous">
    <origin rpy="0.0 0.0 0.0" xyz="0.0 0.0 0.0"/>
    <parent link="sgcmg_frame_4"/>
    <child link="gimbal_frame_4"/>
    <axis xyz="0.0 0.0 1.0"/>
    <limit effort="0.0" lower="0.0" upper="0.0" velocity="0.0"/>
  </joint>
  <!-- Joint at Reaction wheel spin Axis -->
  <!-- <joint name="rw_${id}_to_sgcmg_frame_${id}" type="continuous">  -->
  <joint name="wheel_4" type="continuous">
    <origin rpy="0.0 0.0 0.0" xyz="0.0 0.0 0.0"/>
    <parent link="gimbal_frame_4"/>
    <child link="rw_frame_4"/>
    <axis xyz="0.0 1.0 0.0"/>
    <limit effort="0.0" lower="0.0" upper="0.0" velocity="0.0"/>
  </joint>
  <!-- or -->
  <!-- 
        <xacro:sgcmg id = "0" parent = "platform" r  = "0.0735" h = "0.059" yaw="0"/>
        <xacro:sgcmg id = "1" parent = "platform" r  = "0.0735" h = "0.059" yaw="90"/>
        <xacro:sgcmg id = "2" parent = "platform" r  = "0.0735" h = "0.059" yaw="180"/>
        <xacro:sgcmg id = "3" parent = "platform" r  = "0.0735" h = "0.059"u yaw="270"/>
    -->
  <link name="tripod">
    <inertial>
      <origin rpy="0.0 0.0 0.0" xyz="0.0 0.0 0.0"/>
      <mass value="0.0"/>
      <inertia ixx="0.0" ixy="0.0" ixz="0.0" iyy="0.0" iyz="0.0" izz="0.0"/>
    </inertial>
    <visual name="">
      <origin rpy="0.0 0.0 0.0" xyz="0.0 0.0 0.05"/>
      <geometry>
        <mesh filename="package://vscmg_description/meshes/tripod.stl" scale="0.001 0.001 0.001"/>
      </geometry>
      <material name="tripod_color"/>
    </visual>
    <collision>
      <origin rpy="0.0 0.0 0.0" xyz="0.0 0.0 0.05"/>
      <geometry>
        <mesh filename="package://vscmg_description/meshes/tripod.stl" scale="0.001 0.001 0.001"/>
      </geometry>
    </collision>
  </link>
  <link name="world"/>
  <joint name="tripod_world" type="fixed">
    <origin rpy="0.0 0.0 0.0" xyz="0.0 0.0 0.0"/>
    <parent link="world"/>
    <child link="tripod"/>
    <limit effort="0.0" lower="0.0" upper="0.0" velocity="0.0"/>
  </joint>
  <joint name="tripod_flaoting" type="fixed">
    <origin rpy="0.0 0.0 0.0" xyz="0.0 0.0 0.0"/>
    <parent link="tripod"/>
    <child link="floating_base"/>
    <limit effort="0.0" lower="0.0" upper="0.0" velocity="0.0"/>
  </joint>
</robot>

